2022-02-26 15:16:10,640 INFO    MainThread:25395 [wandb_setup.py:_flush():75] Loading settings from /opt/ml/.config/wandb/settings
2022-02-26 15:16:10,640 INFO    MainThread:25395 [wandb_setup.py:_flush():75] Loading settings from /opt/ml/baseline/wandb/settings
2022-02-26 15:16:10,641 INFO    MainThread:25395 [wandb_setup.py:_flush():75] Loading settings from environment variables: {}
2022-02-26 15:16:10,641 INFO    MainThread:25395 [wandb_setup.py:_flush():75] Inferring run settings from compute environment: {'program_relpath': 'train.py', 'program': 'train.py'}
2022-02-26 15:16:10,641 INFO    MainThread:25395 [wandb_init.py:_log_setup():386] Logging user logs to /opt/ml/baseline/wandb/run-20220226_151610-2bx5bre0/logs/debug.log
2022-02-26 15:16:10,641 INFO    MainThread:25395 [wandb_init.py:_log_setup():387] Logging internal logs to /opt/ml/baseline/wandb/run-20220226_151610-2bx5bre0/logs/debug-internal.log
2022-02-26 15:16:10,641 INFO    MainThread:25395 [wandb_init.py:init():420] calling init triggers
2022-02-26 15:16:10,641 INFO    MainThread:25395 [wandb_init.py:init():425] wandb.init called with sweep_config: {}
config: {'epochs': 10, 'batch_size': 32, 'learning_rate': 0.0002}
2022-02-26 15:16:10,641 INFO    MainThread:25395 [wandb_init.py:init():471] starting backend
2022-02-26 15:16:10,641 INFO    MainThread:25395 [backend.py:_multiprocessing_setup():99] multiprocessing start_methods=fork,spawn,forkserver, using: spawn
2022-02-26 15:16:10,654 INFO    MainThread:25395 [backend.py:ensure_launched():219] starting backend process...
2022-02-26 15:16:10,668 INFO    MainThread:25395 [backend.py:ensure_launched():224] started backend process with pid: 25431
2022-02-26 15:16:10,669 INFO    MainThread:25395 [wandb_init.py:init():480] backend started and connected
2022-02-26 15:16:10,673 INFO    MainThread:25395 [wandb_init.py:init():550] updated telemetry
2022-02-26 15:16:10,675 INFO    MainThread:25395 [wandb_init.py:init():581] communicating current version
2022-02-26 15:16:11,532 INFO    MainThread:25395 [wandb_init.py:init():586] got version response 
2022-02-26 15:16:11,532 INFO    MainThread:25395 [wandb_init.py:init():596] communicating run to backend with 30 second timeout
2022-02-26 15:16:11,822 INFO    MainThread:25395 [wandb_init.py:init():624] starting run threads in backend
2022-02-26 15:16:14,833 INFO    MainThread:25395 [wandb_run.py:_console_start():1827] atexit reg
2022-02-26 15:16:14,833 INFO    MainThread:25395 [wandb_run.py:_redirect():1701] redirect: SettingsConsole.REDIRECT
2022-02-26 15:16:14,833 INFO    MainThread:25395 [wandb_run.py:_redirect():1706] Redirecting console.
2022-02-26 15:16:14,836 INFO    MainThread:25395 [wandb_run.py:_redirect():1762] Redirects installed.
2022-02-26 15:16:14,836 INFO    MainThread:25395 [wandb_init.py:init():651] run started, returning control to user process
2022-02-26 15:16:18,128 INFO    MainThread:25395 [wandb_watch.py:watch():43] Watching
2022-02-26 15:16:20,568 INFO    MainThread:25395 [wandb_run.py:_atexit_cleanup():1797] got exitcode: 255
2022-02-26 15:16:20,573 INFO    MainThread:25395 [wandb_run.py:_restore():1769] restore
2022-02-26 15:16:23,312 INFO    MainThread:25395 [wandb_run.py:_restore():1769] restore
2022-02-26 15:16:26,200 ERROR   MainThread:25395 [wandb_run.py:_atexit_cleanup():1815] Problem finishing run
Traceback (most recent call last):
  File "/opt/conda/lib/python3.8/site-packages/wandb/sdk/wandb_run.py", line 1805, in _atexit_cleanup
    self._on_finish()
  File "/opt/conda/lib/python3.8/site-packages/wandb/sdk/wandb_run.py", line 1953, in _on_finish
    self._console_stop()  # TODO: there's a race here with jupyter console logging
  File "/opt/conda/lib/python3.8/site-packages/wandb/sdk/wandb_run.py", line 1845, in _console_stop
    self._restore()
  File "/opt/conda/lib/python3.8/site-packages/wandb/sdk/wandb_run.py", line 1775, in _restore
    self._err_redir.uninstall()
  File "/opt/conda/lib/python3.8/site-packages/wandb/sdk/lib/redirect.py", line 747, in uninstall
    self._emulator_write_thread.join(timeout=5)
  File "/opt/conda/lib/python3.8/threading.py", line 1015, in join
    self._wait_for_tstate_lock(timeout=max(timeout, 0))
  File "/opt/conda/lib/python3.8/threading.py", line 1027, in _wait_for_tstate_lock
    elif lock.acquire(block, timeout):
  File "/opt/conda/lib/python3.8/site-packages/wandb/sdk/lib/redirect.py", line 649, in handler
    self.handle_window_size_change()
  File "/opt/conda/lib/python3.8/site-packages/wandb/sdk/lib/redirect.py", line 680, in handle_window_size_change
    fcntl.ioctl(fd, termios.TIOCSWINSZ, win_size)
OSError: [Errno 9] Bad file descriptor
