2022-02-27 11:59:52,330 INFO    MainThread:28694 [wandb_setup.py:_flush():75] Loading settings from /opt/ml/.config/wandb/settings
2022-02-27 11:59:52,331 INFO    MainThread:28694 [wandb_setup.py:_flush():75] Loading settings from /opt/ml/baseline/wandb/settings
2022-02-27 11:59:52,331 INFO    MainThread:28694 [wandb_setup.py:_flush():75] Loading settings from environment variables: {}
2022-02-27 11:59:52,331 INFO    MainThread:28694 [wandb_setup.py:_flush():75] Inferring run settings from compute environment: {'program_relpath': 'trainA.py', 'program': 'trainA.py'}
2022-02-27 11:59:52,331 INFO    MainThread:28694 [wandb_init.py:_log_setup():386] Logging user logs to /opt/ml/baseline/wandb/run-20220227_115952-qsgc2ntb/logs/debug.log
2022-02-27 11:59:52,331 INFO    MainThread:28694 [wandb_init.py:_log_setup():387] Logging internal logs to /opt/ml/baseline/wandb/run-20220227_115952-qsgc2ntb/logs/debug-internal.log
2022-02-27 11:59:52,331 INFO    MainThread:28694 [wandb_init.py:init():420] calling init triggers
2022-02-27 11:59:52,331 INFO    MainThread:28694 [wandb_init.py:init():425] wandb.init called with sweep_config: {}
config: {'epochs': 15, 'batch_size': 64, 'learning_rate': 0.001}
2022-02-27 11:59:52,331 INFO    MainThread:28694 [wandb_init.py:init():471] starting backend
2022-02-27 11:59:52,331 INFO    MainThread:28694 [backend.py:_multiprocessing_setup():99] multiprocessing start_methods=fork,spawn,forkserver, using: spawn
2022-02-27 11:59:52,345 INFO    MainThread:28694 [backend.py:ensure_launched():219] starting backend process...
2022-02-27 11:59:52,360 INFO    MainThread:28694 [backend.py:ensure_launched():224] started backend process with pid: 28727
2022-02-27 11:59:52,376 INFO    MainThread:28694 [wandb_init.py:init():480] backend started and connected
2022-02-27 11:59:52,379 INFO    MainThread:28694 [wandb_init.py:init():550] updated telemetry
2022-02-27 11:59:52,380 INFO    MainThread:28694 [wandb_init.py:init():581] communicating current version
2022-02-27 11:59:53,218 INFO    MainThread:28694 [wandb_init.py:init():586] got version response 
2022-02-27 11:59:53,218 INFO    MainThread:28694 [wandb_init.py:init():596] communicating run to backend with 30 second timeout
2022-02-27 11:59:53,468 INFO    MainThread:28694 [wandb_init.py:init():624] starting run threads in backend
2022-02-27 11:59:56,334 INFO    MainThread:28694 [wandb_run.py:_console_start():1827] atexit reg
2022-02-27 11:59:56,334 INFO    MainThread:28694 [wandb_run.py:_redirect():1701] redirect: SettingsConsole.REDIRECT
2022-02-27 11:59:56,335 INFO    MainThread:28694 [wandb_run.py:_redirect():1706] Redirecting console.
2022-02-27 11:59:56,337 INFO    MainThread:28694 [wandb_run.py:_redirect():1762] Redirects installed.
2022-02-27 11:59:56,337 INFO    MainThread:28694 [wandb_init.py:init():651] run started, returning control to user process
2022-02-27 11:59:59,688 INFO    MainThread:28694 [wandb_watch.py:watch():43] Watching
2022-02-27 12:15:10,833 INFO    MainThread:28694 [wandb_run.py:_atexit_cleanup():1797] got exitcode: 255
2022-02-27 12:15:10,876 INFO    MainThread:28694 [wandb_run.py:_restore():1769] restore
2022-02-27 12:15:13,195 INFO    MainThread:28694 [wandb_run.py:_restore():1769] restore
2022-02-27 12:15:19,172 ERROR   MainThread:28694 [wandb_run.py:_atexit_cleanup():1815] Problem finishing run
Traceback (most recent call last):
  File "/opt/conda/lib/python3.8/site-packages/wandb/sdk/wandb_run.py", line 1805, in _atexit_cleanup
    self._on_finish()
  File "/opt/conda/lib/python3.8/site-packages/wandb/sdk/wandb_run.py", line 1953, in _on_finish
    self._console_stop()  # TODO: there's a race here with jupyter console logging
  File "/opt/conda/lib/python3.8/site-packages/wandb/sdk/wandb_run.py", line 1845, in _console_stop
    self._restore()
  File "/opt/conda/lib/python3.8/site-packages/wandb/sdk/wandb_run.py", line 1775, in _restore
    self._err_redir.uninstall()
  File "/opt/conda/lib/python3.8/site-packages/wandb/sdk/lib/redirect.py", line 747, in uninstall
    self._emulator_write_thread.join(timeout=5)
  File "/opt/conda/lib/python3.8/threading.py", line 1015, in join
    self._wait_for_tstate_lock(timeout=max(timeout, 0))
  File "/opt/conda/lib/python3.8/threading.py", line 1027, in _wait_for_tstate_lock
    elif lock.acquire(block, timeout):
  File "/opt/conda/lib/python3.8/site-packages/wandb/sdk/lib/redirect.py", line 649, in handler
    self.handle_window_size_change()
  File "/opt/conda/lib/python3.8/site-packages/wandb/sdk/lib/redirect.py", line 680, in handle_window_size_change
    fcntl.ioctl(fd, termios.TIOCSWINSZ, win_size)
OSError: [Errno 9] Bad file descriptor
